Workbook

Sheet 총괄
A1: 2026년 국제크루즈 선석배정 결과(2026. 7. 18. 기준)
A2: 구분 | B2: 선명 | C2: 톤수 (ton) | D2: 정원 (명) | E2: 배정내역 | H2: 비고
E3: 계 | F3: 제주항 | G3: 서귀포항
A4: 선사 | B4: 선박 | E4: =SUM(E5:E59) -> 321 | F4: =SUM(F5:F59) -> 122 | G4: =SUM(G5:G59) -> 199
A5: Costa Cruises | B5: COSTA SERENA | C5: 114261 | D5: 3617 | E5: =SUM(F5:G5) -> 3 | F5: =COUNTIF('제주항(JEJU)'!$C$2:$C$188,총괄!B5) -> 0 | G5: =COUNTIF('서귀포(SEOGWIPO)'!$C$2:$C$523,총괄!B5) -> 3
A6: NYK Cruises Japan | B6: ASUKA2 | C6: 50444 | D6: 960 | E6: =SUM(F6:G6) -> 0 | F6: =COUNTIF('제주항(JEJU)'!$C$2:$C$119,총괄!B6) -> 0 | G6: =COUNTIF('서귀포(SEOGWIPO)'!$C$2:$C$523,총괄!B6) -> 0
B7: ASUKA3 | C7: 50444 | D7: 960 | E7: =SUM(F7:G7) -> 0 | F7: =COUNTIF('제주항(JEJU)'!$C$2:$C$119,총괄!B7) -> 0 | G7: =COUNTIF('서귀포(SEOGWIPO)'!$C$2:$C$523,총괄!B7) -> 0
A8: AIDA Cruises | B8: AIDA STELLA | C8: 71304 | D8: 2964 | E8: =SUM(F8:G8) -> 0 | F8: =COUNTIF('제주항(JEJU)'!$C$2:$C$119,총괄!B8) -> 0 | G8: =COUNTIF('서귀포(SEOGWIPO)'!$C$2:$C$523,총괄!B8) -> 0
A9: Princess Cruises | B9: DIAMOND PRINCESS | C9: 115906 | D9: 3247 | E9: =SUM(F9:G9) -> 2 | F9: =COUNTIF('제주항(JEJU)'!$C$2:$C$188,총괄!B9) -> 0 | G9: =COUNTIF('서귀포(SEOGWIPO)'!$C$2:$C$523,총괄!B9) -> 2
A10: Celebrity Cruises(Royal Caribbean) | B10: CELEBRITY MILLENNIUM | C10: 90963 | D10: 2590 | E10: =SUM(F10:G10) -> 5 | F10: =COUNTIF('제주항(JEJU)'!$C$2:$C$188,총괄!B10) -> 5 | G10: =COUNTIF('서귀포(SEOGWIPO)'!$C$2:$C$523,총괄!B10) -> 0
A11: Cunard | B11: Queen Elizabeth | C11: 90901 | D11: 2092 | E11: =SUM(F11:G11) -> 0 | F11: =COUNTIF('제주항(JEJU)'!$C$2:$C$119,총괄!B11) -> 0 | G11: =COUNTIF('서귀포(SEOGWIPO)'!$C$2:$C$523,총괄!B11) -> 0
A12: Venus Cruise Line(Japan) | B12: EASTERN VENUS | C12: 26594 | D12: 720 | E12: =SUM(F12:G12) -> 0 | F12: =COUNTIF('제주항(JEJU)'!$C$2:$C$119,총괄!B12) -> 0 | G12: =COUNTIF('서귀포(SEOGWIPO)'!$C$2:$C$523,총괄!B12) -> 0
A13: Oceania Cruises | B13: MS REGATTA | C13: 30277 | D13: 803 | E13: =SUM(F13:G13) -> 2 | F13: =COUNTIF('제주항(JEJU)'!$C$2:$C$188,총괄!B13) -> 2 | G13: =COUNTIF('서귀포(SEOGWIPO)'!$C$2:$C$523,총괄!B13) -> 0
B14: MS Sirena | C14: 30277 | D14: 803 | E14: =SUM(F14:G14) -> 0 | F14: =COUNTIF('제주항(JEJU)'!$C$2:$C$188,총괄!B14) -> 0 | G14: =COUNTIF('서귀포(SEOGWIPO)'!$C$2:$C$523,총괄!B14) -> 0
A15: Regent Seven Seas Cruises | B15: MS Seven Seas Explorer | C15: 55254 | D15: 829 | E15: =SUM(F15:G15) -> 0 | F15: =COUNTIF('제주항(JEJU)'!$C$2:$C$119,총괄!B15) -> 0 | G15: =COUNTIF('서귀포(SEOGWIPO)'!$C$2:$C$523,총괄!B15) -> 0
A16: Carnival Corporation | B16: NOORDAM | C16: 82897 | D16: 2380 | E16: =SUM(F16:G16) -> 0 | F16: =COUNTIF('제주항(JEJU)'!$C$2:$C$119,총괄!B16) -> 0 | G16: =COUNTIF('서귀포(SEOGWIPO)'!$C$2:$C$523,총괄!B16) -> 0
A17: TUI Cruises | B17: Mein Schiff 6 | C17: 98811 | D17: 2794 | E17: =SUM(F17:G17) -> 0 | F17: =COUNTIF('제주항(JEJU)'!$C$2:$C$119,총괄!B17) -> 0 | G17: =COUNTIF('서귀포(SEOGWIPO)'!$C$2:$C$523,총괄!B17) -> 0
A18: Carnival Corporation | B18: Carnival Luminosa | C18: 97720 | D18: 2712 | E18: =SUM(F18:G18) -> 1 | F18: =COUNTIF('제주항(JEJU)'!$C$2:$C$188,총괄!B18) -> 0 | G18: =COUNTIF('서귀포(SEOGWIPO)'!$C$2:$C$523,총괄!B18) -> 1
A19: Crystal Cruises | B19: Crystal Symphony | C19: 51068 | D19: 606 | E19: =SUM(F19:G19) -> 4 | F19: =COUNTIF('제주항(JEJU)'!$C$2:$C$188,총괄!B19) -> 4 | G19: =COUNTIF('서귀포(SEOGWIPO)'!$C$2:$C$523,총괄!B19) -> 0
A20: ResidenSea | B20: The World | C20: 43524 | D20: 200 | E20: =SUM(F20:G20) -> 1 | F20: =COUNTIF('제주항(JEJU)'!$C$2:$C$188,총괄!B20) -> 1 | G20: =COUNTIF('서귀포(SEOGWIPO)'!$C$2:$C$523,총괄!B20) -> 0
A21: Peace Boat Cruise | B21: PACIFIC WORLD | C21: 77441 | D21: 2271 | E21: =SUM(F21:G21) -> 0 | F21: =COUNTIF('제주항(JEJU)'!$C$2:$C$119,총괄!B21) -> 0 | G21: =COUNTIF('서귀포(SEOGWIPO)'!$C$2:$C$523,총괄!B21) -> 0
A22: Holland America | B22: Westerdam | C22: 82862 | D22: 2362 | E22: =SUM(F22:G22) -> 2 | F22: =COUNTIF('제주항(JEJU)'!$C$2:$C$188,총괄!B22) -> 2 | G22: =COUNTIF('서귀포(SEOGWIPO)'!$C$2:$C$523,총괄!B22) -> 0
A23: Hapag-Lloyd Cruise | B23: HANSEATIC SPIRIT | C23: 15540 | D23: 230 | E23: =SUM(F23:G23) -> 0 | F23: =COUNTIF('제주항(JEJU)'!$C$2:$C$119,총괄!B23) -> 0 | G23: =COUNTIF('서귀포(SEOGWIPO)'!$C$2:$C$523,총괄!B23) -> 0
B24: EUROPA 2 | C24: 42830 | D24: 706 | E24: =SUM(F24:G24) -> 0 | F24: =COUNTIF('제주항(JEJU)'!$C$2:$C$119,총괄!B24) -> 0 | G24: =COUNTIF('서귀포(SEOGWIPO)'!$C$2:$C$523,총괄!B24) -> 0
A25: Villa Vie Odyssey Ltd | B25: Odyssey | C25: 24344 | D25: 970 | E25: =SUM(F25:G25) -> 0 | F25: =COUNTIF('제주항(JEJU)'!$C$2:$C$119,총괄!B25) -> 0 | G25: =COUNTIF('서귀포(SEOGWIPO)'!$C$2:$C$523,총괄!B25) -> 0
A26: MSC | B26: MSC Bellissima | C26: 171598 | D26: 5686 | E26: =SUM(F26:G26) -> 28 | F26: =COUNTIF('제주항(JEJU)'!$C$2:$C$188,총괄!B26) -> 0 | G26: =COUNTIF('서귀포(SEOGWIPO)'!$C$2:$C$523,총괄!B26) -> 28
A27: Coral Princess Cruises (Australia) | B27: Coral Geographer | C27: 5602 | D27: 120 | E27: =SUM(F27:G27) -> 0 | F27: =COUNTIF('제주항(JEJU)'!$C$2:$C$119,총괄!B27) -> 0 | G27: =COUNTIF('서귀포(SEOGWIPO)'!$C$2:$C$523,총괄!B27) -> 0
B28: Coral Princess | C28: 91627 | D28: 2390 | E28: =SUM(F28:G28) -> 1 | F28: =COUNTIF('제주항(JEJU)'!$C$2:$C$188,총괄!B28) -> 0 | G28: =COUNTIF('서귀포(SEOGWIPO)'!$C$2:$C$523,총괄!B28) -> 1
A29: Mitsui OSK Lines (MOL Mitsui Ocean Cruises) | B29: Nippon Maru | C29: 22472 | D29: 607 | E29: =SUM(F29:G29) -> 1 | F29: =COUNTIF('제주항(JEJU)'!$C$2:$C$188,총괄!B29) -> 1 | G29: =COUNTIF('서귀포(SEOGWIPO)'!$C$2:$C$523,총괄!B29) -> 0
B30: Mitsui Ocean Fuji | C30: 32477 | D30: 540 | E30: =SUM(F30:G30) -> 6 | F30: =COUNTIF('제주항(JEJU)'!$C$2:$C$188,총괄!B30) -> 6 | G30: =COUNTIF('서귀포(SEOGWIPO)'!$C$2:$C$523,총괄!B30) -> 0
A31: Norwegian Cruise Line | B31: NORWEGIAN SKY | C31: 77104 | D31: 2405 | E31: =SUM(F31:G31) -> 0 | F31: =COUNTIF('제주항(JEJU)'!$C$2:$C$119,총괄!B31) -> 0 | G31: =COUNTIF('서귀포(SEOGWIPO)'!$C$2:$C$523,총괄!B31) -> 0
B32: NORWEGIAN SPIRIT | C32: 75904 | D32: 2414 | E32: =SUM(F32:G32) -> 0 | F32: =COUNTIF('제주항(JEJU)'!$C$2:$C$119,총괄!B32) -> 0 | G32: =COUNTIF('서귀포(SEOGWIPO)'!$C$2:$C$523,총괄!B32) -> 0
B33: Norwegian Jade | C33: 93558 | D33: 2882 | E33: =SUM(F33:G33) -> 2 | F33: =COUNTIF('제주항(JEJU)'!$C$2:$C$188,총괄!B33) -> 2 | G33: =COUNTIF('서귀포(SEOGWIPO)'!$C$2:$C$523,총괄!B33) -> 0
B34: NORWEGIAN SUN | C34: 78309 | D34: 2323 | E34: =SUM(F34:G34) -> 0 | F34: =COUNTIF('제주항(JEJU)'!$C$2:$C$119,총괄!B34) -> 0 | G34: =COUNTIF('서귀포(SEOGWIPO)'!$C$2:$C$523,총괄!B34) -> 0
A35: NYK Cruises Japan | B35: Asuka 2 | C35: 50444 | D35: 960 | E35: =SUM(F35:G35) -> 1 | F35: =COUNTIF('제주항(JEJU)'!$C$2:$C$188,총괄!B35) -> 1 | G35: =COUNTIF('서귀포(SEOGWIPO)'!$C$2:$C$523,총괄!B35) -> 0
B36: Asuka 3 | C36: 52183 | D36: 744 | E36: =SUM(F36:G36) -> 2 | F36: =COUNTIF('제주항(JEJU)'!$C$2:$C$188,총괄!B36) -> 2 | G36: =COUNTIF('서귀포(SEOGWIPO)'!$C$2:$C$523,총괄!B36) -> 0
A37: Silversea Cruises | B37: Silver Muse | C37: 40791 | D37: 623 | E37: =SUM(F37:G37) -> 1 | F37: =COUNTIF('제주항(JEJU)'!$C$2:$C$188,총괄!B37) -> 1 | G37: =COUNTIF('서귀포(SEOGWIPO)'!$C$2:$C$523,총괄!B37) -> 0
B38: Silver Moon | C38: 40700 | D38: 691 | E38: =SUM(F38:G38) -> 2 | F38: =COUNTIF('제주항(JEJU)'!$C$2:$C$188,총괄!B38) -> 2 | G38: =COUNTIF('서귀포(SEOGWIPO)'!$C$2:$C$523,총괄!B38) -> 0
B39: SCENIC ECLIPSE II | C39: 22498 | D39: 228 | E39: =SUM(F39:G39) -> 0 | F39: =COUNTIF('제주항(JEJU)'!$C$2:$C$119,총괄!B39) -> 0 | G39: =COUNTIF('서귀포(SEOGWIPO)'!$C$2:$C$523,총괄!B39) -> 0
B40: SILVER WHISPER | C40: 28258 | D40: 466 | E40: =SUM(F40:G40) -> 0 | F40: =COUNTIF('제주항(JEJU)'!$C$2:$C$119,총괄!B40) -> 0 | G40: =COUNTIF('서귀포(SEOGWIPO)'!$C$2:$C$523,총괄!B40) -> 0
...

Sheet 제주항(JEJU)
A1: 연번 | B1: 배정 | C1: 선명 | D1: 입항시간 | E1: 출항시간 | F1: 체류 시간 | G1: 톤수 | H1: 승객정원 | I1: 최초 출발항 | J1: 이전항 | K1: 다음항
A2: 1 | B2: 제주항 | C2: Dream | D2: 46027.333 | E2: 46027.667 | F2: =TEXT((VALUE(E2)-VALUE(D2))*24,"0.0") -> 8.0 | G2: 77499 | H2: 2270 | I2: Tianjin, CN | J2: Tianjin, CN | K2: Incheon, KR
A3: 2 | B3: 제주항 | C3: Dream | D3: 46038.5 | E3: 46038.833 | F3: =TEXT((VALUE(E3)-VALUE(D3))*24,"0.0") -> 8.0 | G3: 77499 | H3: 2270 | I3: Tianjin, CN | J3: Incheon, KR | K3: Tianjin, CN
A4: 3 | B4: 제주항 | C4: Dream | D4: 46047.333 | E4: 46047.667 | F4: =TEXT((VALUE(E4)-VALUE(D4))*24,"0.0") -> 8.0 | G4: 77499 | H4: 2270 | I4: Tianjin, CN | J4: Tianjin, CN | K4: Incheon, KR
A5: 4 | B5: 제주항 | C5: Dream | D5: 46053.5 | E5: 46053.833 | F5: =TEXT((VALUE(E5)-VALUE(D5))*24,"0.0") -> 8.0 | G5: 77499 | H5: 2270 | I5: Tianjin, CN | J5: Incheon, KR | K5: Tianjin, CN
A6: 5 | B6: 제주항 | C6: Dream | D6: 46057.333 | E6: 46057.667 | F6: =TEXT((VALUE(E6)-VALUE(D6))*24,"0.0") -> 8.0 | G6: 77499 | H6: 2270 | I6: Tianjin, CN | J6: Tianjin, CN | K6: Incheon, KR
A7: 6 | B7: 제주항 | C7: Dream | D7: 46062.375 | E7: 46062.708 | F7: =TEXT((VALUE(E7)-VALUE(D7))*24,"0.0") -> 8.0 | G7: 77499 | H7: 2270 | I7: Tianjin, CN | J7: Tianjin, CN | K7: Incheon, KR
A8: 7 | B8: 제주항 | C8: Dream | D8: 46067.333 | E8: 46067.667 | F8: =TEXT((VALUE(E8)-VALUE(D8))*24,"0.0") -> 8.0 | G8: 77499 | H8: 2270 | I8: Tianjin, CN | J8: Tianjin, CN | K8: Incheon, KR
A9: 8 | B9: 제주항 | C9: MS Regatta | D9: 46072.292 | E9: 46072.708 | F9: =TEXT((VALUE(E9)-VALUE(D9))*24,"0.0") -> 10.0 | G9: 30277 | H9: 803 | I9: Hong Kong, HK | J9: Busan, KR | K9: Incheon, KR
A10: 9 | B10: 제주항 | C10: Dream | D10: 46073.5 | E10: 46073.833 | F10: =TEXT((VALUE(E10)-VALUE(D10))*24,"0.0") -> 8.0 | G10: 77499 | H10: 2270 | I10: Tianjin, CN | J10: Incheon, KR | K10: Tianjin, CN
A11: 10 | B11: 제주항 | C11: Dream | D11: 46085.583 | E11: 46085.917 | F11: =TEXT((VALUE(E11)-VALUE(D11))*24,"0.0") -> 8.0 | G11: 77499 | H11: 2270 | I11: Shanghai, CN | J11: Shanghai, CN | K11: Busan, KR
A12: 11 | B12: 제주항 | C12: MS Regatta | D12: 46090.333 | E12: 46090.708 | F12: =TEXT((VALUE(E12)-VALUE(D12))*24,"0.0") -> 9.0 | G12: 30277 | H12: 803 | I12: Shanghai, CN | J12: Shanghai, CN | K12: Keelung, TW
A13: 12 | B13: 제주항 | C13: Dream | D13: 46093.583 | E13: 46093.917 | F13: =TEXT((VALUE(E13)-VALUE(D13))*24,"0.0") -> 8.0 | G13: 77499 | H13: 2270 | I13: Shanghai, CN | J13: Shanghai, CN | K13: Busan, KR
... A72: 71 | B72: 제주항 | C72: Adora Mediterranea | D72: 46248.333 | E72: 46248.667 | F72: =TEXT((VALUE(E72)-VALUE(D72))*24,"0.0") -> 8.0 | G72: 85619 | H72: 2680 | I72: Tianjin, CN | J72: Tianjin, CN | K72: Incheon, KR
A73: 72 | B73: 제주항 | C73: Dream | D73: 46249.625 | E73: 46250.917 | F73: =TEXT((VALUE(E73)-VALUE(D73))*24,"0.0") -> 31.0 | G73: 77499 | H73: 2270 | I73: Shanghai, CN | J73: Shanghai, CN | K73: Shanghai, CN | L73: Overnight Curfew(터미널 이동제한 시간) : 22:30 ~ 7:30
A74: 73 | B74: 제주항 | C74: Star Navigator | D74: 46252.292 | E74: 46252.75 | F74: =TEXT((VALUE(E74)-VALUE(D74))*24,"0.0") -> 11.0 | G74: 75338 | H74: 2500 | I74: Keelung, TW | J74: Keelung, TW | K74: Nagasaki, JP
A75: 74 | B75: 제주항 | C75: Adora Mediterranea | D75: 46253.333 | E75: 46253.667 | F75: =TEXT((VALUE(E75)-VALUE(D75))*24,"0.0") -> 8.0 | G75: 85619 | H75: 2680 | I75: Tianjin, CN | J75: Tianjin, CN | K75: Incheon, KR
A76: 75 | B76: 제주항 | C76: Mitsui Ocean Fuji | D76: 46254.292 | E76: 46254.75 | F76: =TEXT((VALUE(E76)-VALUE(D76))*24,"0.0") -> 11.0 | G76: 32477 | H76: 540 | I76: Yokohama, JP | J76: Saiki, JP | K76: Kagosima, JP
A77: 76 | B77: 제주항 | C77: Dream | D77: 46257.583 | E77: 46257.917 | F77: =TEXT((VALUE(E77)-VALUE(D77))*24,"0.0") -> 8.0 | G77: 77499 | H77: 2270 | I77: Shanghai, CN | J77: Shanghai, CN | K77: Busan, KR
A78: 77 | B78: 제주항 | C78: Adora Mediterranea | D78: 46258.333 | E78: 46258.667 | F78: =TEXT((VALUE(E78)-VALUE(D78))*24,"0.0") -> 8.0 | G78: 85619 | H78: 2680 | I78: Tianjin, CN | J78: Tianjin, CN | K78: Incheon, KR
A79: 78 | B79: 제주항 | C79: Dream | D79: 46261.583 | E79: 46261.917 | F79: =TEXT((VALUE(E79)-VALUE(D79))*24,"0.0") -> 8.0 | G79: 77499 | H79: 2270 | I79: Shanghai, CN | J79: Shanghai, CN | K79: Busan, KR
A80: 79 | B80: 제주항 | C80: Mitsui Ocean Fuji | D80: 46263.333 | E80: 46263.75 | F80: =TEXT((VALUE(E80)-VALUE(D80))*24,"0.0") -> 10.0 | G80: 32477 | H80: 540 | I80: Yokohama, JP | J80: Nagasaki, JP | K80: Yokohama, JP
A81: 80 | B81: 제주항 | C81: Dream | D81: 46265.583 | E81: 46265.917 | F81: =TEXT((VALUE(E81)-VALUE(D81))*24,"0.0") -> 8.0 | G81: 77499 | H81: 2270 | I81: Shanghai, CN | J81: Shanghai, CN | K81: Busan, KR
A82: 81 | B82: 제주항 | C82: Star Navigator | D82: 46266.292 | E82: 46266.75 | F82: =TEXT((VALUE(E82)-VALUE(D82))*24,"0.0") -> 11.0 | G82: 75338 | H82: 2500 | I82: Keelung, TW | J82: Keelung, TW | K82: Nagasaki, JP
A83: 82 | B83: 제주항 | C83: Dream | D83: 46269.583 | E83: 46269.917 | F83: =TEXT((VALUE(E83)-VALUE(D83))*24,"0.0") -> 8.0 | G83: 77499 | H83: 2270 | I83: Shanghai, CN | J83: Shanghai, CN | K83: Busan, KR
A84: 83 | B84: 제주항 | C84: Asuka 3 | D84: 46270.333 | E84: 46270.708 | F84: =TEXT((VALUE(E84)-VALUE(D84))*24,"0.0") -> 9.0 | G84: 52183 | H84: 744 | I84: Hakata, JP | J84: Hakata, JP | K84: Hakata, JP
A85: 84 | B85: 제주항 | C85: Adora Mediterranea | D85: 46271.542 | E85: 46271.875 | F85: =TEXT((VALUE(E85)-VALUE(D85))*24,"0.0") -> 8.0 | G85: 85619 | H85: 2680 | I85: Shanghai, CN | J85: Shanghai, CN | K85: Nagasaki, JP
... A100: 99 | B100: 제주항 | C100: Dream | D100: 46305.583 | E100: 46305.917 | F100: =TEXT((VALUE(E100)-VALUE(D100))*24,"0.0") -> 8.0 | G100: 77499 | H100: 2270 | I100: Shanghai, CN | J100: Shanghai, CN | K100: Busan, KR
A101: 100 | B101: 제주항 | C101: The World | D101: 46308.375 | E101: 46309.958 | F101: =TEXT((VALUE(E101)-VALUE(D101))*24,"0.0") -> 38.0 | G101: 43524 | H101: 200 | I101: Tokyo, JP | J101: Tokyo, JP | K101: Dalian, CN | L101: Overnight Curfew(터미널 이동제한 시간) : 22:30 ~ 7:30
A102: 101 | B102: 제주항 | C102: Adora Mediterranea | D102: 46309.292 | E102: 46309.625 | F102: =TEXT((VALUE(E102)-VALUE(D102))*24,"0.0") -> 8.0 | G102: 85619 | H102: 2680 | I102: Dalian, CN | J102: Incheon, KR | K102: Dalian, CN
A103: 102 | B103: 제주항 | C103: Adora Mediterranea | D103: 46313.312 | E103: 46313.646 | F103: =TEXT((VALUE(E103)-VALUE(D103))*24,"0.0") -> 8.0 | G103: 85619 | H103: 2680 | I103: Dalian, CN | J103: Busan, KR | K103: Dalian, CN
A104: 103 | B104: 제주항 | C104: Dream | D104: 46317.583 | E104: 46317.917 | F104: =TEXT((VALUE(E104)-VALUE(D104))*24,"0.0") -> 8.0 | G104: 77499 | H104: 2270 | I104: Shanghai, CN | J104: Shanghai, CN | K104: Busan, KR
A105: 104 | B105: 제주항 | C105: Silver Moon | D105: 46318.333 | E105: 46318.708 | F105: =TEXT((VALUE(E105)-VALUE(D105))*24,"0.0") -> 9.0 | G105: 40700 | H105: 691 | I105: Yokohama, JP | J105: Busan, KR | K105: Incheon, KR
A106: 105 | B106: 제주항 | C106: Silver Moon | D106: 46321.375 | E106: 46321.708 | F106: =TEXT((VALUE(E106)-VALUE(D106))*24,"0.0") -> 8.0 | G106: 40700 | H106: 691 | I106: Tokyo, JP | J106: Incheon, KR | K106: Nagasaki, JP
A107: 106 | B107: 제주항 | C107: Mitsui Ocean Fuji | D107: 46322.333 | E107: 46322.708 | F107: =TEXT((VALUE(E107)-VALUE(D107))*24,"0.0") -> 9.0 | G107: 32477 | H107: 450 | I107: Tokyo, JP | J107: Motobu, JP | K107: Hakata, JP
A108: 107 | B108: 제주항 | C108: Asuka 3 | D108: 46325.333 | E108: 46325.708 | F108: =TEXT((VALUE(E108)-VALUE(D108))*24,"0.0") -> 9.0 | G108: 52183 | H108: 744 | I108: Hakata, JP | J108: Hakata, JP | K108: Hakata, JP
A109: 108 | B109: 제주항 | C109: Westerdam | D109: 46328.417 | E109: 46328.708 | F109: =TEXT((VALUE(E109)-VALUE(D109))*24,"0.0") -> 7.0 | G109: 82862 | H109: 2362 | I109: Tokyo, JP | J109: Nagasaki, JP | K109: Busan, KR
A110: 109 | B110: 제주항 | C110: Dream | D110: 46329.583 | E110: 46329.917 | F110: =TEXT((VALUE(E110)-VALUE(D110))*24,"0.0") -> 8.0 | G110: 77499 | H110: 2270 | I110: Shanghai, CN | J110: Shanghai, CN | K110: Busan, KR
A111: 110 | B111: 제주항 | C111: Silver Muse | D111: 46330.292 | E111: 46330.75 | F111: =TEXT((VALUE(E111)-VALUE(D111))*24,"0.0") -> 11.0 | G111: 40791 | H111: 623 | I111: Tokyo, JP | J111: Nagasaki, JP | K111: Keelung, TW
A112: 111 | B112: 제주항 | C112: Dream | D112: 46341.458 | E112: 46341.792 | F112: =TEXT((VALUE(E112)-VALUE(D112))*24,"0.0") -> 8.0 | G112: 77499 | H112: 2270 | I112: Tianjin, CN | J112: Sasebo, JP | K112: Tianjin, CN
...

Sheet 서귀포(SEOGWIPO)
A1: 연번 | B1: 배정 | C1: 선명 | D1: 입항시간 | E1: 출항시간 | F1: 체류 시간 | G1: 톤수 | H1: 승객정원 | I1: 최초 출발항 | J1: 이전항 | K1: 다음항
A2: 1 | B2: 강정1 | C2: Adora Magic City | D2: 46026.542 | E2: 46026.875 | F2: =TEXT((VALUE(E2)-VALUE(D2))*24,"0.0") -> 8.0 | G2: 136201 | H2: 5246 | I2: Shanghai, CN | J2: Shanghai, CN | K2: Busan, KR
A3: 2 | B3: 강정1 | C3: Adora Magic City | D3: 46030.542 | E3: 46030.875 | F3: =TEXT((VALUE(E3)-VALUE(D3))*24,"0.0") -> 8.0 | G3: 136201 | H3: 5246 | I3: Shanghai, CN | J3: Shanghai, CN | K3: Busan, KR
A4: 3 | B4: 강정1 | C4: Adora Magic City | D4: 46034.542 | E4: 46034.875 | F4: =TEXT((VALUE(E4)-VALUE(D4))*24,"0.0") -> 8.0 | G4: 136201 | H4: 5246 | I4: Shanghai, CN | J4: Shanghai, CN | K4: Busan, KR
A5: 4 | B5: 강정1 | C5: Adora Magic City | D5: 46038.542 | E5: 46038.875 | F5: =TEXT((VALUE(E5)-VALUE(D5))*24,"0.0") -> 8.0 | G5: 136201 | H5: 5246 | I5: Shanghai, CN | J5: Shanghai, CN | K5: Busan, KR
A6: 5 | B6: 강정1 | C6: Adora Magic City | D6: 46042.542 | E6: 46042.875 | F6: =TEXT((VALUE(E6)-VALUE(D6))*24,"0.0") -> 8.0 | G6: 136201 | H6: 5246 | I6: Shanghai, CN | J6: Shanghai, CN | K6: Busan, KR
A7: 6 | B7: 강정1 | C7: Adora Magic City | D7: 46046.542 | E7: 46046.875 | F7: =TEXT((VALUE(E7)-VALUE(D7))*24,"0.0") -> 8.0 | G7: 136201 | H7: 5246 | I7: Shanghai, CN | J7: Shanghai, CN | K7: Busan, KR
A8: 7 | B8: 강정1 | C8: Adora Magic City | D8: 46050.542 | E8: 46051.917 | F8: =TEXT((VALUE(E8)-VALUE(D8))*24,"0.0") -> 33.0 | G8: 136201 | H8: 5246 | I8: Shanghai, CN | J8: Shanghai, CN | K8: Shanghai, CN | L8: Overnight Curfew(터미널 이동제한 시간) : 22:30 ~ 7:30
A9: 8 | B9: 강정2 | C9: MSC Bellissima | D9: 46050.625 | E9: 46050.917 | F9: =TEXT((VALUE(E9)-VALUE(D9))*24,"0.0") -> 7.0 | G9: 171598 | H9: 5686 | I9: Shanghai, CN | J9: Shanghai, CN | K9: Busan, KR
A10: 9 | B10: 강정1 | C10: MSC Bellissima | D10: 46054.625 | E10: 46054.917 | F10: =TEXT((VALUE(E10)-VALUE(D10))*24,"0.0") -> 7.0 | G10: 171598 | H10: 5686 | I10: Shanghai, CN | J10: Shanghai, CN | K10: Busan, KR
A11: 10 | B11: 강정2 | C11: Adora Magic City | D11: 46054.542 | E11: 46055.917 | F11: =TEXT((VALUE(E11)-VALUE(D11))*24,"0.0") -> 33.0 | G11: 136201 | H11: 5246 | I11: Shanghai, CN | J11: Shanghai, CN | K11: Shanghai, CN | L11: Overnight Curfew(터미널 이동제한 시간) : 22:30 ~ 7:30
A12: 11 | B12: 강정1 | C12: Adora Magic City | D12: 46058.542 | E12: 46058.875 | F12: =TEXT((VALUE(E12)-VALUE(D12))*24,"0.0") -> 8.0 | G12: 136201 | H12: 5246 | I12: Shanghai, CN | J12: Shanghai, CN | K12: Busan, KR
A13: 12 | B13: 강정1 | C13: Adora Magic City | D13: 46062.542 | E13: 46062.875 | F13: =TEXT((VALUE(E13)-VALUE(D13))*24,"0.0") -> 8.0 | G13: 136201 | H13: 5246 | I13: Shanghai, CN | J13: Shanghai, CN | K13: Busan, KR
A14: 13 | B14: 강정1 | C14: MSC Bellissima | D14: 46068.375 | E14: 46069.5 | F14: =TEXT((VALUE(E14)-VALUE(D14))*24,"0.0") -> 27.0 | G14: 171598 | H14: 5686 | I14: Shanghai, CN | J14: Busan, KR | K14: Shanghai, CN | L14: Overnight Curfew(터미널 이동제한 시간) : 22:30 ~ 7:30
A15: 14 | B15: 강정1 | C15: Adora Magic City | D15: 46072.583 | E15: 46072.958 | F15: =TEXT((VALUE(E15)-VALUE(D15))*24,"0.0") -> 9.0 | G15: 136201 | H15: 5246 | I15: Shanghai, CN | J15: Incheon, KR | K15: Shanghai, CN
A16: 15 | B16: 강정1 | C16: Spectrum of The Seas | D16: 46073.292 | E16: 46073.875 | F16: =TEXT((VALUE(E16)-VALUE(D16))*24,"0.0") -> 14.0 | G16: 169379 | H16: 5622 | I16: Shanghai, CN | J16: Shanghai, CN | K16: Shanghai, CN
A17: 16 | B17: 강정1 | C17: Adora Magic City | D17: 46075.542 | E17: 46075.875 | F17: =TEXT((VALUE(E17)-VALUE(D17))*24,"0.0") -> 8.0 | G17: 136201 | H17: 5246 | I17: Shanghai, CN | J17: Shanghai, CN | K17: Busan, KR
A18: 17 | B18: 강정1 | C18: MSC Bellissima | D18: 46080.583 | E18: 46080.917 | F18: =TEXT((VALUE(E18)-VALUE(D18))*24,"0.0") -> 8.0 | G18: 171598 | H18: 5686 | I18: Shanghai, CN | J18: Shanghai, CN | K18: Busan, KR
A19: 18 | B19: 강정1 | C19: MSC Bellissima | D19: 46084.583 | E19: 46084.917 | F19: =TEXT((VALUE(E19)-VALUE(D19))*24,"0.0") -> 8.0 | G19: 171598 | H19: 5686 | I19: Shanghai, CN | J19: Shanghai, CN | K19: Busan, KR
A20: 19 | B20: 강정1 | C20: Adora Magic City | D20: 46087.542 | E20: 46087.875 | F20: =TEXT((VALUE(E20)-VALUE(D20))*24,"0.0") -> 8.0 | G20: 136201 | H20: 5246 | I20: Shanghai, CN | J20: Shanghai, CN | K20: Busan, KR
A21: 20 | B21: 강정2 | C21: Spectrum of The Seas | D21: 46087.292 | E21: 46087.792 | F21: =TEXT((VALUE(E21)-VALUE(D21))*24,"0.0") -> 12.0 | G21: 169379 | H21: 5622 | I21: Shanghai, CN | J21: Shanghai, CN | K21: Busan, KR
A22: 21 | B22: 강정1 | C22: Adora Magic City | D22: 46091.542 | E22: 46091.875 | F22: =TEXT((VALUE(E22)-VALUE(D22))*24,"0.0") -> 8.0 | G22: 136201 | H22: 5246 | I22: Shanghai, CN | J22: Shanghai, CN | K22: Busan, KR
A23: 22 | B23: 강정1 | C23: Spectrum of The Seas | D23: 46092.292 | E23: 46092.792 | F23: =TEXT((VALUE(E23)-VALUE(D23))*24,"0.0") -> 12.0 | G23: 169379 | H23: 5622 | I23: Shanghai, CN | J23: Busan, KR | K23: Shanghai, CN
A24: 23 | B24: 강정1 | C24: Adora Magic City | D24: 46095.542 | E24: 46095.875 | F24: =TEXT((VALUE(E24)-VALUE(D24))*24,"0.0") -> 8.0 | G24: 136201 | H24: 5246 | I24: Shanghai, CN | J24: Shanghai, CN | K24: Yeosu, KR
A25: 24 | B25: 강정1 | C25: Spectrum of The Seas | D25: 46096.292 | E25: 46096.792 | F25: =TEXT((VALUE(E25)-VALUE(D25))*24,"0.0") -> 12.0 | G25: 169379 | H25: 5622 | I25: Shanghai, CN | J25: Shanghai, CN | K25: Shanghai, CN
A26: 25 | B26: 강정1 | C26: Costa Serena | D26: 46097.292 | E26: 46097.667 | F26: =TEXT((VALUE(E26)-VALUE(D26))*24,"0.0") -> 9.0 | G26: 114261 | H26: 3617 | I26: Manila, PH | J26: Fukuoka, JP | K26: Manila, PH
A27: 26 | B27: 강정1 | C27: Adora Magic City | D27: 46099.542 | E27: 46100.875 | F27: =TEXT((VALUE(E27)-VALUE(D27))*24,"0.0") -> 32.0 | G27: 136201 | H27: 5246 | I27: Shanghai, CN | J27: Shanghai, CN | K27: Shanghai, CN | L27: Overnight Curfew(터미널 이동제한 시간) : 22:30 ~ 7:30
A28: 27 | B28: 강정1 | C28: Visio | D28: 46102.604 | E28: 46102.875 | F28: =TEXT((VALUE(E28)-VALUE(D28))*24,"0.0") -> 6.5 | G28: 102784 | H28: 3470 | I28: Tianjin, CN | J28: Busan, KR | K28: Tianjin, CN
A29: 28 | B29: 강정1 | C29: Adora Magic City | D29: 46103.542 | E29: 46103.875 | F29: =TEXT((VALUE(E29)-VALUE(D29))*24,"0.0") -> 8.0 | G29: 136201 | H29: 5246 | I29: Shanghai, CN | J29: Shanghai, CN | K29: Busan, KR
A30: 29 | B30: 강정1 | C30: Adora Magic City | D30: 46107.542 | E30: 46108.875 | F30: =TEXT((VALUE(E30)-VALUE(D30))*24,"0.0") -> 32.0 | G30: 136201 | H30: 5246 | I30: Shanghai, CN | J30: Shanghai, CN | K30: Shanghai, CN | L30: Overnight Curfew(터미널 이동제한 시간) : 22:30 ~ 7:30
A31: 30 | B31: 강정1 | C31: Adora Magic City | D31: 46111.542 | E31: 46111.875 | F31: =TEXT((VALUE(E31)-VALUE(D31))*24,"0.0") -> 8.0 | G31: 136201 | H31: 5246 | I31: Shanghai, CN | J31: Shanghai, CN | K31: Busan, KR
A32: 31 | B32: 강정1 | C32: Adora Magic City | D32: 46115.542 | E32: 46115.875 | F32: =TEXT((VALUE(E32)-VALUE(D32))*24,"0.0") -> 8.0 | G32: 136201 | H32: 5246 | I32: Shanghai, CN | J32: Shanghai, CN | K32: Busan, KR
A33: 32 | B33: 강정1 | C33: Dream | D33: 46117.583 | E33: 46117.917 | F33: =TEXT((VALUE(E33)-VALUE(D33))*24,"0.0") -> 8.0 | G33: 77499 | H33: 2270 | I33: Shanghai, CN | J33: Shanghai, CN | K33: Busan, KR
A34: 33 | B34: 강정2 | C34: Visio | D34: 46117.5 | E34: 46117.833 | F34: =TEXT((VALUE(E34)-VALUE(D34))*24,"0.0") -> 8.0 | G34: 102784 | H34: 3470 | I34: Tianjin, CN | J34: Incheon, KR | K34: Tianjin, CN
A35: 34 | B35: 강정1 | C35: MSC Bellissima | D35: 46118.458 | E35: 46118.875 | F35: =TEXT((VALUE(E35)-VALUE(D35))*24,"0.0") -> 10.0 | G35: 171598 | H35: 5686 | I35: Tokyo, JP | J35: Kanazawa, JP | K35: Sasebo, JP
A36: 35 | B36: 강정1 | C36: Adora Magic City | D36: 46119.542 | E36: 46119.875 | F36: =TEXT((VALUE(E36)-VALUE(D36))*24,"0.0") -> 8.0 | G36: 136201 | H36: 5246 | I36: Shanghai, CN | J36: Shanghai, CN | K36: Busan, KR
A37: 36 | B37: 강정1 | C37: Spectrum of The Seas | D37: 46120.292 | E37: 46120.792 | F37: =TEXT((VALUE(E37)-VALUE(D37))*24,"0.0") -> 12.0 | G37: 169379 | H37: 5622 | I37: Shanghai, CN | J37: Shanghai, CN | K37: Shanghai, CN
A38: 37 | B38: 강정1 | C38: Coral Princess | D38: 46121.292 | E38: 46121.625 | F38: =TEXT((VALUE(E38)-VALUE(D38))*24,"0.0") -> 8.0 | G38: 91627 | H38: 2390 | I38: Keelung, TW | J38: Keelung, TW | K38: Nagasaki, JP
A39: 38 | B39: 강정1 | C39: Adora Magic City | D39: 46123.542 | E39: 46123.917 | F39: =TEXT((VALUE(E39)-VALUE(D39))*24,"0.0") -> 9.0 | G39: 136201 | H39: 5246 | I39: Shanghai, CN | J39: Shanghai, CN | K39: Shanghai, CN
A40: 39 | B40: 강정1 | C40: Visio | D40: 46126.333 | E40: 46126.667 | F40: =TEXT((VALUE(E40)-VALUE(D40))*24,"0.0") -> 8.0 | G40: 102784 | H40: 3470 | I40: Tianjin, CN | J40: Tianjin, CN | K40: Incheon, KR
...

Sheet 총괄(항구분없음)
A1: 2025년 국제크루즈 선석신청
A2: 구 분 | B2: 선 명 | C2: 톤수(ton) | D2: 정원(명) | E2: 항차 | F2: 비고
A4: 16개선사 | B4: 29척 | E4: =SUM(E5:E36) -> 305
A5: 코스타 | B5: COSTA SERENA | C5: 114147 | D5: 5260 | E5: =COUNTIF(통합!$E$2:$E$684,'총괄(항구분없음)'!B5) -> 3 | F5: 일본발/중국발
A6: NYK크루즈 | B6: ASUKA2 | C6: 50444 | D6: 960 | E6: =COUNTIF(통합!$E$2:$E$684,'총괄(항구분없음)'!B6) -> 1 | F6: 일본발
A7: AIDA 크루즈 | B7: AIDA STELLA | C7: 71304 | D7: 2964 | E7: =COUNTIF(통합!$E$2:$E$684,'총괄(항구분없음)'!B7) -> 1 | F7: 월드와이드
A8: 프린세스 | B8: DIAMOND PRINCESS | C8: 115906 | D8: 3102 | E8: =COUNTIF(통합!$E$2:$E$684,'총괄(항구분없음)'!B8) -> 6 | F8: 일본발
A9: CELEBRITY | B9: CELEBRITY MILLENNIUM | C9: 90963 | D9: 2593 | E9: =COUNTIF(통합!$E$2:$E$684,'총괄(항구분없음)'!B9) -> 7 | F9: 일본발
A10: Cunard 크루즈 | B10: Queen Elizabeth | C10: 90901 | D10: 2092 | E10: =COUNTIF(통합!$E$2:$E$684,'총괄(항구분없음)'!B10) -> 1 | F10: 홍콩발
A11: Oceania Cruises | B11: MS REGATTA | C11: 30277 | D11: 803 | E11: =COUNTIF(통합!$E$2:$E$684,'총괄(항구분없음)'!B11) -> 1 | F11: 월드와이드
A12: Regent Seven Seas Cruises | B12: MS Seven Seas Explorer | C12: 55254 | D12: 829 | E12: =COUNTIF(통합!$E$2:$E$684,'총괄(항구분없음)'!B12) -> 1 | F12: 월드와이드
A13: Carnival Corporation | B13: NOORDAM | C13: 82897 | D13: 2380 | E13: =COUNTIF(통합!$E$2:$E$684,'총괄(항구분없음)'!B13) -> 1 | F13: 월드와이드
A14: Crystal Cruises, | B14: Crystal Symphony | C14: 51044 | D14: 606 | E14: =COUNTIF(통합!$E$2:$E$684,'총괄(항구분없음)'!B14) -> 1 | F14: 일본발
A15: MSC | B15: MSC BELLISSIMA | C15: 171598 | D15: 5654 | E15: =COUNTIF(통합!$E$2:$E$684,'총괄(항구분없음)'!B15) -> 19 | F15: 일본발/중국발
A16: MSC | B16: MSC SPLENDIDA | C16: 137936 | D16: 4363 | E16: =COUNTIF(통합!$E$2:$E$684,'총괄(항구분없음)'!B16) -> 11 | F16: 일본발/중국발
... A36: 텐진오리엔탈국제크루즈 | B36: DREAM | C36: 77499 | D36: 2222 | E36: =COUNTIF(통합!$E$2:$E$684,'총괄(항구분없음)'!B36) -> 65 | F36: 중국발
A38: 범례 : 일정표 분홍색(하루 2척의 크루즈선 입항)

Sheet 통합
A1: 연번(NO) | B1: 요청항 | C1: 배정(PORT) | D1: 일자 (date) | E1: 선명 (ship Name) | F1: 출발항 (start port) | G1: 입항시간 (IN) | H1: 출항시간 (OUT) | I1: 전출항지 (Previous Port) | J1: 차항지 (Next Port) | K1: 체류기간 (Hours of Stay) | L1: 톤수 | M1: 승객정원
A2: 1 | B2: 제주 | C2: 제주 | D2: 45658 | E2: MITSUI OCEAN FUJI | F2: Yokohama, JP | G2: 0.29166667 | H2: 0.70833333 | I2: Hakata,JP | J2: Busan, KR | K2: =TEXT((VALUE(H2)-VALUE(G2))*24,"0.0") -> 10.0 | L2: 32477 | M2: 458
A3: 2 | B3: 제주 | C3: 강정 | D3: 45658 | E3: DREAM | F3: Tianjin, CN | G3: 0.41666667 | H3: 0.75 | I3: Nagasaki,JP | J3: Tianjin, CN | K3: =TEXT((VALUE(H3)-VALUE(G3))*24,"0.0") -> 8.0 | L3: 77499 | M3: 2222
A4: 3 | B4: 제주 | C4: 제주 | D4: 45660 | E4: PIANO LAND | F4: Shanghai,CN | G4: 0.54166667 | H4: 0.875 | I4: Shanghai,CN | J4: Fukuoka, JP | K4: =TEXT((VALUE(H4)-VALUE(G4))*24,"0.0") -> 8.0 | L4: 49840 | M4: 1975
A5: 4 | B5: 강정 | C5: 강정 | D5: 45661 | E5: Adora Magic City | F5: Shanghai,CN | G5: 0.58333333 | H5: 0.9375 | I5: Shanghai,CN | J5: Nagasaki.JP | K5: =TEXT((VALUE(H5)-VALUE(G5))*24,"0.0") -> 8.5 | L5: 135500 | M5: 5246
A6: 5 | B6: 제주 | C6: 제주 | D6: 45663 | E6: DREAM | F6: Tianjin, CN | G6: 0.41666667 | H6: 0.75 | I6: Fukuoka, JP | J6: Tianjin, CN | K6: =TEXT((VALUE(H6)-VALUE(G6))*24,"0.0") -> 8.0 | L6: 77499 | M6: 2222
A7: 6 | B7: 제주 | C7: 제주 | D7: 45664 | E7: PIANO LAND | F7: Shanghai,CN | G7: 0.54166667 | H7: 0.875 | I7: Shanghai,CN | J7: Fukuoka, JP | K7: =TEXT((VALUE(H7)-VALUE(G7))*24,"0.0") -> 8.0 | L7: 49840 | M7: 1975
A8: 7 | B8: 강정 | C8: 강정 | D8: 45666 | E8: MSC SPLENDIDA | F8: Hong Kong, HK | G8: 0.58333333 | H8: 0.91666667 | I8: Naha, JP | J8: Xiamen, CN | K8: =TEXT((VALUE(H8)-VALUE(G8))*24,"0.0") -> 8.0 | L8: 137936 | M8: 4363
A9: 8 | B9: 제주 | C9: 제주 | D9: 45667 | E9: ZHAO SHANG YI DUN | F9: Shanghai,CN | G9: 0.33333333 | H9: 0.66666667 | I9: Yatsushiro, JP | J9: Osaka, JP | K9: =TEXT((VALUE(H9)-VALUE(G9))*24,"0.0") -> 8.0 | L9: 47842 | M9: 954
A10: 9 | B10: 제주 | C10: 제주 | D10: 45668 | E10: PIANO LAND | F10: Shanghai,CN | G10: 0.54166667 | H10: 0.875 | I10: Shanghai,CN | J10: Nagasaki, JP | K10: =TEXT((VALUE(H10)-VALUE(G10))*24,"0.0") -> 8.0 | L10: 49840 | M10: 1975
A11: 10 | B11: 제주 | C11: 강정 | D11: 45668 | E11: DREAM | F11: Tianjin, CN | G11: 0.41666667 | H11: 0.75 | I11: Nagasaki,JP | J11: Tianjin, CN | K11: =TEXT((VALUE(H11)-VALUE(G11))*24,"0.0") -> 8.0 | L11: 77499 | M11: 2222
A12: 11 | B12: 강정 | C12: 강정 | D12: 45669 | E12: Adora Magic City | F12: Shanghai,CN | G12: 0.58333333 | H12: 0.9375 | I12: Shanghai,CN | J12: Fukuoka, JP | K12: =TEXT((VALUE(H12)-VALUE(G12))*24,"0.0") -> 8.5 | L12: 135500 | M12: 5246
A13: 12 | B13: 제주 | C13: 제주 | D13: 45672 | E13: PIANO LAND | F13: Shanghai,CN | G13: 0.54166667 | H13: 0.875 | I13: Shanghai,CN | J13: Fukuoka, JP | K13: =TEXT((VALUE(H13)-VALUE(G13))*24,"0.0") -> 8.0 | L13: 49840 | M13: 1975
... A36: 35 | B36: 강정 | C36: 강정 | D36: 45708 | E36: DREAM | F36: Tianjin, CN | G36: 0.41666667 | H36: 0.75 | I36: Nagasaki,JP | J36: Tianjin, CN | K36: =TEXT((VALUE(H36)-VALUE(G36))*24,"0.0") -> 8.0 | L36: 77499 | M36: 2222
A37: 36 | B37: 제주 | C37: 제주 | D37: 45712 | E37: Nippon Maru | F37: Yokohama, JP | G37: 0.375 | H37: 1 | I37: Kobe, JP | K37: =TEXT((VALUE(H37)-VALUE(G37))*24,"0.0") -> 15.0 | L37: 22472 | M37: 607
B38: 제주 | C38: 제주 | D38: 45713 | F38: Yokohama, JP | H38: 0.70833333 | J38: Kobe, JP | K38: =TEXT((VALUE(H38)-VALUE(G38))*24,"0.0") -> 17.0 | L38: 22472 | M38: 607
A39: 37 | B39: 강정 | C39: 강정 | D39: 45713 | E39: DREAM | F39: Tianjin, CN | G39: 0.41666667 | H39: 0.75 | I39: Fukuoka, JP | J39: Tianjin, CN | K39: =TEXT((VALUE(H39)-VALUE(G39))*24,"0.0") -> 8.0 | L39: 77499 | M39: 2222
A40: 38 | B40: 제주 | C40: 제주 | D40: 45716 | E40: PIANO LAND | F40: Shanghai,CN | G40: 0.54166667 | H40: 0.875 | I40: Shanghai,CN | J40: Fukuoka, JP | K40: =TEXT((VALUE(H40)-VALUE(G40))*24,"0.0") -> 8.0 | L40: 49840 | M40: 1975
A41: 39 | B41: 제주 | C41: 제주 | D41: 45718 | E41: DREAM | F41: Tianjin, CN | G41: 0.41666667 | H41: 0.75 | I41: Fukuoka, JP | J41: Tianjin, CN | K41: =TEXT((VALUE(H41)-VALUE(G41))*24,"0.0") -> 8.0 | L41: 77499 | M41: 2222
A42: 40 | B42: 강정 | C42: 강정 | D42: 45717 | E42: MSC BELLISSIMA | F42: Shanghai,CN | G42: 0.54166667 | H42: 0.875 | I42: Shanghai,CN | J42: Fukuoka, JP | K42: =TEXT((VALUE(H42)-VALUE(G42))*24,"0.0") -> 8.0 | L42: 171598 | M42: 5654
A43: 41 | B43: 강정 | C43: 강정 | D43: 45719 | E43: MSC SPLENDIDA | F43: Xiamen, CN | G43: 0.58333333 | H43: 0.875 | I43: Naha, JP | J43: Xiamen, CN | K43: =TEXT((VALUE(H43)-VALUE(G43))*24,"0.0") -> 7.0 | L43: 137936 | M43: 4363
A44: 42 | B44: 제주 | C44: 제주 | D44: 45720 | E44: PIANO LAND | F44: Shanghai,CN | G44: 0.54166667 | H44: 0.875 | I44: Shanghai,CN | J44: Fukuoka, JP | K44: =TEXT((VALUE(H44)-VALUE(G44))*24,"0.0") -> 8.0 | L44: 49840 | M44: 1975
A45: 43 | B45: 강정 | C45: 강정 | D45: 45722 | E45: Spectrum of the seas | F45: Shanghai,CN | G45: 0.54166667 | H45: 0.875 | I45: Shanghai,CN | J45: Nagasaki.JP | K45: =TEXT((VALUE(H45)-VALUE(G45))*24,"0.0") -> 8.0 | L45: 169379 | M45: 5622
A46: 44 | B46: 강정 | C46: 강정 | D46: 45723 | E46: Adora Magic City | F46: Shanghai,CN | G46: 0.58333333 | H46: 0.9375 | I46: Shanghai,CN | J46: Nagasaki.JP | K46: =TEXT((VALUE(H46)-VALUE(G46))*24,"0.0") -> 8.5 | L46: 135500 | M46: 5246
A47: 45 | B47: 제주 | C47: 제주 | D47: 45723 | E47: DREAM | F47: Tianjin, CN | G47: 0.41666667 | H47: 0.75 | I47: Fukuoka, JP | J47: Tianjin, CN | K47: =TEXT((VALUE(H47)-VALUE(G47))*24,"0.0") -> 8.0 | L47: 77499 | M47: 2222
A48: 46 | B48: 제주 | C48: 제주 | D48: 45724 | E48: PIANO LAND | F48: Shanghai,CN | G48: 0.54166667 | H48: 0.875 | I48: Shanghai,CN | J48: Nagasaki, JP | K48: =TEXT((VALUE(H48)-VALUE(G48))*24,"0.0") -> 8.0 | L48: 49840 | M48: 1975
A49: 47 | B49: 제주 | C49: 제주 | D49: 45726 | E49: ZHAO SHANG YI DUN | F49: Yokohama, JP | G49: 0.29166667 | H49: 0.75 | I49: Hakata,JP | J49: Naha,JP | K49: =TEXT((VALUE(H49)-VALUE(G49))*24,"0.0") -> 11.0 | L49: 47842 | M49: 954
A50: 48 | B50: 강정 | C50: 강정 | D50: 45727 | E50: Adora Magic City | F50: Shanghai,CN | G50: 0.58333333 | H50: 0.9375 | I50: Shanghai,CN | J50: Fukuoka, JP | K50: =TEXT((VALUE(H50)-VALUE(G50))*24,"0.0") -> 8.5 | L50: 135500 | M50: 5246
... A307: 305 | B307: 강정 | C307: 강정 | D307: 46014 | E307: Adora Magic City | F307: Shanghai,CN | G307: 0.58333333 | H307: 0.9375 | I307: Shanghai,CN | J307: Fukuoka, JP | K307: =TEXT((VALUE(H307)-VALUE(G307))*24,"0.0") -> 8.5 | L307: 135500 | M307: 5246
